Workbook

Sheet Рычаги
A1: Рычаги финмодели WIF · 36 месяцев
A2: Синим — правится руками. Жёлтым — допущения, которых в стратегии нет: их первыми заменить фактом. Поток клиентов, чеки и штат по месяцам — синие строки на листе «Модель».
A4: Рычаг | B4: Значение | C4: Откуда
A5: ТРУД · ИИ-СОТРУДНИКИ
A6: Отток компаний в месяц | B6: 0.01 | C6: target-state-18m.md: не выше 1%
A7: Цена пилота, $ разово | B7: 4000 | C7: 90-day-plan.md: $3–5 тыс.
A8: ЛИЧНОСТЬ · ПЕРСОНАЖИ
A9: Цена подписки, $/мес | B9: 10 | C9: target-state-18m.md
A10: Отток подписчиков в месяц | B10: 0.08 | C10: target-state-18m.md
A11: Конверсия визита в подписку | B11: 0.01 | C11: target-state-18m.md
A12: Чек сделки с брендом, $ | B12: 50000 | C12: target-state-18m.md
A13: КАПИТАЛ · УЧЁТ РАСХОДОВ НА ИИ
A14: Отток компаний в месяц | B14: 0.015 | C14: Допущение: в стратегии нет
A15: КОМАНДА
A16: Полная стоимость ставки, $/год | B16: 150000 | C16: roles.md: вилка 120–200 тыс.
A17: Стоимость найма, $ на человека | B17: 15000 | C17: Допущение: рекрутинг и онбординг
A18: СЕБЕСТОИМОСТЬ, ДОЛЯ ВЫРУЧКИ
A19: Труд: инференс и проверка работы агента | B19: 0.3 | C19: Допущение
A20: Подписка: платформы, хостинг, поддержка | B20: 0.25 | C20: Допущение
A21: Бренды: производство под заказ | B21: 0.4 | C21: Допущение
A22: Капитал: инфраструктура биллинга | B22: 0.15 | C22: Допущение
A23: ПРИВЛЕЧЕНИЕ
A24: Комиссия продажам, доля годового контракта Труда | B24: 0.1 | C24: Допущение
A25: Маркетинг на одну компанию Труда, $ | B25: 5000 | C25: Допущение
A26: Маркетинг на одну компанию Капитала, $ | B26: 300 | C26: Допущение
A27: Стоимость визита в Личности, $ | B27: 0.2 | C27: Допущение — самое непроверенное
A28: ПОСТОЯННЫЕ, $ В МЕСЯЦ
A29: Производство выпусков Личности | B29: 120000 | C29: Допущение
A30: Общая платформа: модели, хостинг, инструменты | B30: 80000 | C30: Допущение
A31: Юрлица США/ЕС, аудит, комплаенс | B31: 60000 | C31: Допущение
A32: Офис, поездки, софт — доля ФОТ | B32: 0.15 | C32: Допущение
A33: ДЕНЬГИ
A34: Раунд, $ | B34: 50000000 | C34: Дека v10
A35: ОЦЕНКА — МУЛЬТИПЛИКАТОРЫ
A36: Труд, × ARR | B36: 10 | C36: Допущение: проверить по сделкам-аналогам
A37: Капитал, × ARR | B37: 10 | C37: Допущение
A38: Подписка, × ARR | B38: 4 | C38: Допущение
A39: Бренды, × выручки за 12 месяцев | B39: 1.5 | C39: Допущение

Sheet Модель
A1: Модель по месяцам · базовый сценарий
A2: Синие строки — план: новые клиенты, визиты, сделки, чеки, штат. Остальное — формулы. База = прошлый месяц − ROUND(прошлый × отток) + новые; все штуки целые.
C3: Год 1 | O3: Год 2 | AA3: Год 3
A4: Месяц | B4: Ед. | C4: 1 | D4: 2 | E4: 3 | F4: 4 | G4: 5 | H4: 6 | I4: 7 | J4: 8 | K4: 9 | L4: 10 | M4: 11 | N4: 12 | O4: 13 | P4: 14 | Q4: 15 | R4: 16 | S4: 17 | T4: 18 | U4: 19 | V4: 20 | W4: 21 | X4: 22 | Y4: 23 | Z4: 24 | AA4: 25 | AB4: 26 | AC4: 27 | AD4: 28 | AE4: 29 | AF4: 30 | AG4: 31 | AH4: 32 | AI4: 33 | AJ4: 34 | AK4: 35 | AL4: 36
A5: ТРУД · ИИ-СОТРУДНИКИ
A6: Новых компаний за месяц | B6: шт. | C6: 0 | D6: 0 | E6: 0 | F6: 2 | G6: 3 | H6: 5 | I6: 5 | J6: 6 | K6: 7 | L6: 9 | M6: 11 | N6: 12 | O6: 14 | P6: 15 | Q6: 17 | R6: 18 | S6: 20 | T6: 21 | U6: 21 | V6: 21 | W6: 21 | X6: 21 | Y6: 21 | Z6: 21 | AA6: 21 | AB6: 21 | AC6: 21 | AD6: 21 | AE6: 21 | AF6: 21 | AG6: 21 | AH6: 21 | AI6: 21 | AJ6: 21 | AK6: 21 | AL6: 21
A7: Компаний | B7: шт. | C7: =C6 -> 0 | D7: =C7-ROUND(C7*Рычаги!$B$6,0)+D6 -> 0 | E7: =D7-ROUND(D7*Рычаги!$B$6,0)+E6 -> 0 | F7: =E7-ROUND(E7*Рычаги!$B$6,0)+F6 -> 2 | G7: =F7-ROUND(F7*Рычаги!$B$6,0)+G6 -> 5 | H7: =G7-ROUND(G7*Рычаги!$B$6,0)+H6 -> 10 | I7: =H7-ROUND(H7*Рычаги!$B$6,0)+I6 -> 15 | J7: =I7-ROUND(I7*Рычаги!$B$6,0)+J6 -> 21 | K7: =J7-ROUND(J7*Рычаги!$B$6,0)+K6 -> 28 | ... AL7: =AK7-ROUND(AK7*Рычаги!$B$6,0)+AL6 -> 480
A8: Платёж компании | B8: $/мес | C8: 0 | D8: 0 | E8: 0 | F8: 0 | G8: 0 | H8: 5000 | I8: 5833.33 | J8: 6666.67 | K8: 7500 | L8: 8333.33 | M8: 9166.67 | N8: 10000 | O8: 10833.33 | P8: 11666.67 | Q8: 12500 | R8: 13333.33 | S8: 14166.67 | T8: 15000 | U8: 15000 | V8: 15000 | W8: 15000 | X8: 15000 | Y8: 15000 | Z8: 15000 | AA8: 15000 | AB8: 15000 | AC8: 15000 | AD8: 15000 | AE8: 15000 | AF8: 15000 | AG8: 15000 | AH8: 15000 | AI8: 15000 | AJ8: 15000 | AK8: 15000 | AL8: 15000
A9: Пилотов запущено | B9: шт. | C9: 0 | D9: 1 | E9: 2 | F9: 2 | G9: 2 | H9: 0 | I9: 0 | J9: 0 | K9: 0 | L9: 0 | M9: 0 | N9: 0 | O9: 0 | P9: 0 | Q9: 0 | R9: 0 | S9: 0 | T9: 0 | U9: 0 | V9: 0 | W9: 0 | X9: 0 | Y9: 0 | Z9: 0 | AA9: 0 | AB9: 0 | AC9: 0 | AD9: 0 | AE9: 0 | AF9: 0 | AG9: 0 | AH9: 0 | AI9: 0 | AJ9: 0 | AK9: 0 | AL9: 0
A10: Выручка Труда | B10: $/мес | C10: =C7*C8+C9*Рычаги!$B$7 -> 0 | D10: =D7*D8+D9*Рычаги!$B$7 -> 4000 | E10: =E7*E8+E9*Рычаги!$B$7 -> 8000 | F10: =F7*F8+F9*Рычаги!$B$7 -> 8000 | G10: =G7*G8+G9*Рычаги!$B$7 -> 8000 | H10: =H7*H8+H9*Рычаги!$B$7 -> 50000 | I10: =I7*I8+I9*Рычаги!$B$7 -> 87499.95 | J10: =J7*J8+J9*Рычаги!$B$7 -> 140000.07 | ... AL10: =AL7*AL8+AL9*Рычаги!$B$7 -> 7200000
A11: ЛИЧНОСТЬ · ПЕРСОНАЖИ
A12: Визитов на платное предложение | B12: в мес. | C12: 0 | D12: 0 | E12: 0 | F12: 0 | G12: 0 | H12: 0 | I12: 0 | J12: 0 | K12: 108325 | L12: 216650 | M12: 324975 | N12: 433300 | O12: 525183 | P12: 617067 | Q12: 708950 | R12: 1005967 | S12: 1302983 | T12: 1600000 | U12: 1600000 | V12: 1600000 | W12: 1600000 | X12: 1600000 | Y12: 1600000 | Z12: 1600000 | AA12: 1600000 | AB12: 1600000 | AC12: 1600000 | AD12: 1600000 | AE12: 1600000 | AF12: 1600000 | AG12: 1600000 | AH12: 1600000 | AI12: 1600000 | AJ12: 1600000 | AK12: 1600000 | AL12: 1600000
A13: Новых подписчиков | B13: чел. | C13: =ROUND(C12*Рычаги!$B$11,0) -> 0 | D13: =ROUND(D12*Рычаги!$B$11,0) -> 0 | E13: =ROUND(E12*Рычаги!$B$11,0) -> 0 | F13: =ROUND(F12*Рычаги!$B$11,0) -> 0 | G13: =ROUND(G12*Рычаги!$B$11,0) -> 0 | H13: =ROUND(H12*Рычаги!$B$11,0) -> 0 | I13: =ROUND(I12*Рычаги!$B$11,0) -> 0 | J13: =ROUND(J12*Рычаги!$B$11,0) -> 0 | ... AL13: =ROUND(AL12*Рычаги!$B$11,0) -> 16000
A14: Подписчиков | B14: чел. | C14: =C13 -> 0 | D14: =C14-ROUND(C14*Рычаги!$B$10,0)+D13 -> 0 | E14: =D14-ROUND(D14*Рычаги!$B$10,0)+E13 -> 0 | F14: =E14-ROUND(E14*Рычаги!$B$10,0)+F13 -> 0 | G14: =F14-ROUND(F14*Рычаги!$B$10,0)+G13 -> 0 | H14: =G14-ROUND(G14*Рычаги!$B$10,0)+H13 -> 0 | I14: =H14-ROUND(H14*Рычаги!$B$10,0)+I13 -> 0 | J14: =I14-ROUND(I14*Рычаги!$B$10,0)+J13 -> 0 | K14: =J14-ROUND(J14*Рычаги!$B$10,0)+K13 -> 1083 | ... AL14: =AK14-ROUND(AK14*Рычаги!$B$10,0)+AL13 -> 167891
A15: Выручка подписки | B15: $/мес | C15: =C14*Рычаги!$B$9 -> 0 | D15: =D14*Рычаги!$B$9 -> 0 | E15: =E14*Рычаги!$B$9 -> 0 | F15: =F14*Рычаги!$B$9 -> 0 | G15: =G14*Рычаги!$B$9 -> 0 | H15: =H14*Рычаги!$B$9 -> 0 | I15: =I14*Рычаги!$B$9 -> 0 | J15: =J14*Рычаги!$B$9 -> 0 | ... AL15: =AL14*Рычаги!$B$9 -> 1678910
A16: Сделок с брендами | B16: шт. | C16: 0 | D16: 0 | E16: 1 | F16: 1 | G16: 1 | H16: 1 | I16: 2 | J16: 3 | K16: 4 | L16: 4 | M16: 4 | N16: 4 | O16: 5 | P16: 5 | Q16: 6 | R16: 7 | S16: 7 | T16: 8 | U16: 8 | V16: 8 | W16: 8 | X16: 8 | Y16: 8 | Z16: 8 | AA16: 8 | AB16: 8 | AC16: 8 | AD16: 8 | AE16: 8 | AF16: 8 | AG16: 8 | AH16: 8 | AI16: 8 | AJ16: 8 | AK16: 8 | AL16: 8
A17: Выручка от брендов | B17: $/мес | C17: =C16*Рычаги!$B$12 -> 0 | D17: =D16*Рычаги!$B$12 -> 0 | E17: =E16*Рычаги!$B$12 -> 50000 | F17: =F16*Рычаги!$B$12 -> 50000 | G17: =G16*Рычаги!$B$12 -> 50000 | H17: =H16*Рычаги!$B$12 -> 50000 | I17: =I16*Рычаги!$B$12 -> 100000 | J17: =J16*Рычаги!$B$12 -> 150000 | ... AL17: =AL16*Рычаги!$B$12 -> 400000
A18: КАПИТАЛ · УЧЁТ РАСХОДОВ НА ИИ
A19: Новых компаний за месяц | B19: шт. | C19: 0 | D19: 0 | E19: 2 | F19: 4 | G19: 5 | H19: 6 | I19: 9 | J19: 11 | K19: 13 | L19: 16 | M19: 18 | N19: 20 | O19: 24 | P19: 28 | Q19: 33 | R19: 37 | S19: 41 | T19: 45 | U19: 45 | V19: 45 | W19: 45 | X19: 45 | Y19: 45 | Z19: 45 | AA19: 45 | AB19: 45 | AC19: 45 | AD19: 45 | AE19: 45 | AF19: 45 | AG19: 45 | AH19: 45 | AI19: 45 | AJ19: 45 | AK19: 45 | AL19: 45
A20: Компаний | B20: шт. | C20: =C19 -> 0 | D20: =C20-ROUND(C20*Рычаги!$B$14,0)+D19 -> 0 | E20: =D20-ROUND(D20*Рычаги!$B$14,0)+E19 -> 2 | F20: =E20-ROUND(E20*Рычаги!$B$14,0)+F19 -> 6 | G20: =F20-ROUND(F20*Рычаги!$B$14,0)+G19 -> 11 | H20: =G20-ROUND(G20*Рычаги!$B$14,0)+H19 -> 17 | I20: =H20-ROUND(H20*Рычаги!$B$14,0)+I19 -> 26 | J20: =I20-ROUND(I20*Рычаги!$B$14,0)+J19 -> 37 | K20: =J20-ROUND(J20*Рычаги!$B$14,0)+K19 -> 49 | ... AL20: =AK20-ROUND(AK20*Рычаги!$B$14,0)+AL19 -> 936
A21: Платёж компании | B21: $/мес | C21: 0 | D21: 0 | E21: 800 | F21: 880 | G21: 960 | H21: 1040 | I21: 1120 | J21: 1200 | K21: 1280 | L21: 1360 | M21: 1440 | N21: 1520 | O21: 1600 | P21: 1680 | Q21: 1760 | R21: 1840 | S21: 1920 | T21: 2000 | U21: 2000 | V21: 2000 | W21: 2000 | X21: 2000 | Y21: 2000 | Z21: 2000 | AA21: 2000 | AB21: 2000 | AC21: 2000 | AD21: 2000 | AE21: 2000 | AF21: 2000 | AG21: 2000 | AH21: 2000 | AI21: 2000 | AJ21: 2000 | AK21: 2000 | AL21: 2000
A22: Выручка Капитала | B22: $/мес | C22: =C20*C21 -> 0 | D22: =D20*D21 -> 0 | E22: =E20*E21 -> 1600 | F22: =F20*F21 -> 5280 | G22: =G20*G21 -> 10560 | H22: =H20*H21 -> 17680 | I22: =I20*I21 -> 29120 | J22: =J20*J21 -> 44400 | ... AL22: =AL20*AL21 -> 1872000
A23: ВЫРУЧКА
A24: Выручка всего | B24: $/мес | C24: =C10+C15+C17+C22 -> 0 | D24: =D10+D15+D17+D22 -> 4000 | E24: =E10+E15+E17+E22 -> 59600 | F24: =F10+F15+F17+F22 -> 63280 | G24: =G10+G15+G17+G22 -> 68560 | H24: =H10+H15+H17+H22 -> 117680 | I24: =I10+I15+I17+I22 -> 216619.95 | J24: =J10+J15+J17+J22 -> 334400.07 | ... AL24: =AL10+AL15+AL17+AL22 -> 11150910
A25: ARR Труда (без пилотов) | B25: $ | C25: =(C10-C9*Рычаги!$B$7)*12 -> 0 | D25: =(D10-D9*Рычаги!$B$7)*12 -> 0 | E25: =(E10-E9*Рычаги!$B$7)*12 -> 0 | F25: =(F10-F9*Рычаги!$B$7)*12 -> 0 | G25: =(G10-G9*Рычаги!$B$7)*12 -> 0 | H25: =(H10-H9*Рычаги!$B$7)*12 -> 600000 | I25: =(I10-I9*Рычаги!$B$7)*12 -> 1049999.4 | J25: =(J10-J9*Рычаги!$B$7)*12 -> 1680000.8 | ... AL25: =(AL10-AL9*Рычаги!$B$7)*12 -> 86400000
A26: ARR группы (без брендов и пилотов) | B26: $ | C26: =C25+(C15+C22)*12 -> 0 | D26: =D25+(D15+D22)*12 -> 0 | E26: =E25+(E15+E22)*12 -> 19200 | F26: =F25+(F15+F22)*12 -> 63360 | G26: =G25+(G15+G22)*12 -> 126720 | H26: =H25+(H15+H22)*12 -> 812160 | I26: =I25+(I15+I22)*12 -> 1399439.4 | J26: =J25+(J15+J22)*12 -> 2212800.8 | ... AL26: =AL25+(AL15+AL22)*12 -> 129010920
A27: СЕБЕСТОИМОСТЬ
A28: Себестоимость | B28: $/мес | C28: =C10*Рычаги!$B$19+C15*Рычаги!$B$20+C17*Рычаги!$B$21+C22*Рычаги!$B$22 -> 0 | D28: =D10*Рычаги!$B$19+D15*Рычаги!$B$20+D17*Рычаги!$B$21+D22*Рычаги!$B$22 -> 1200 | E28: =E10*Рычаги!$B$19+E15*Рычаги!$B$20+E17*Рычаги!$B$21+E22*Рычаги!$B$22 -> 22640 | F28: =F10*Рычаги!$B$19+F15*Рычаги!$B$20+F17*Рычаги!$B$21+F22*Рычаги!$B$22 -> 23192 | G28: =G10*Рычаги!$B$19+G15*Рычаги!$B$20+G17*Рычаги!$B$21+G22*Рычаги!$B$22 -> 23984 | H28: =H10*Рычаги!$B$19+H15*Рычаги!$B$20+H17*Рычаги!$B$21+H22*Рычаги!$B$22 -> 37652 | I28: =I10*Рычаги!$B$19+I15*Рычаги!$B$20+I17*Рычаги!$B$21+I22*Рычаги!$B$22 -> 70617.985 | J28: =J10*Рычаги!$B$19+J15*Рычаги!$B$20+J17*Рычаги!$B$21+J22*Рычаги!$B$22 -> 108660.02 | ... AL28: =AL10*Рычаги!$B$19+AL15*Рычаги!$B$20+AL17*Рычаги!$B$21+AL22*Рычаги!$B$22 -> 3020527.5
A29: Валовая прибыль | B29: $/мес | C29: =C24-C28 -> 0 | D29: =D24-D28 -> 2800 | E29: =E24-E28 -> 36960 | F29: =F24-F28 -> 40088 | G29: =G24-G28 -> 44576 | H29: =H24-H28 -> 80028 | I29: =I24-I28 -> 146001.96 | J29: =J24-J28 -> 225740.05 | ... AL29: =AL24-AL28 -> 8130382.5
A30: ОПЕРАЦИОННЫЕ РАСХОДЫ
A31: Штат | B31: ставок | C31: 10 | D31: 20 | E31: 30 | F31: 38 | G31: 47 | H31: 55 | I31: 62 | J31: 68 | K31: 75 | L31: 82 | M31: 88 | N31: 95 | O31: 102 | P31: 108 | Q31: 115 | R31: 122 | S31: 128 | T31: 135 | U31: 139 | V31: 143 | W31: 148 | X31: 152 | Y31: 156 | Z31: 160 | AA31: 163 | AB31: 165 | AC31: 168 | AD31: 170 | AE31: 173 | AF31: 175 | AG31: 178 | AH31: 180 | AI31: 183 | AJ31: 185 | AK31: 188 | AL31: 190
A32: ФОТ | B32: $/мес | C32: =C31*Рычаги!$B$16/12 -> 125000 | D32: =D31*Рычаги!$B$16/12 -> 250000 | E32: =E31*Рычаги!$B$16/12 -> 375000 | F32: =F31*Рычаги!$B$16/12 -> 475000 | G32: =G31*Рычаги!$B$16/12 -> 587500 | H32: =H31*Рычаги!$B$16/12 -> 687500 | I32: =I31*Рычаги!$B$16/12 -> 775000 | J32: =J31*Рычаги!$B$16/12 -> 850000 | ... AL32: =AL31*Рычаги!$B$16/12 -> 2375000
A33: Найм | B33: $/мес | C33: =0 -> 0 | D33: =MAX(0,D31-C31)*Рычаги!$B$17 -> 150000 | E33: =MAX(0,E31-D31)*Рычаги!$B$17 -> 150000 | F33: =MAX(0,F31-E31)*Рычаги!$B$17 -> 120000 | G33: =MAX(0,G31-F31)*Рычаги!$B$17 -> 135000 | H33: =MAX(0,H31-G31)*Рычаги!$B$17 -> 120000 | I33: =MAX(0,I31-H31)*Рычаги!$B$17 -> 105000 | J33: =MAX(0,J31-I31)*Рычаги!$B$17 -> 90000 | K33: =MAX(0,K31-J31)*Рычаги!$B$17 -> 105000 | ... AL33: =MAX(0,AL31-AK31)*Рычаги!$B$17 -> 30000
A34: Комиссии продажам | B34: $/мес | C34: =C6*C8*12*Рычаги!$B$24 -> 0 | D34: =D6*D8*12*Рычаги!$B$24 -> 0 | E34: =E6*E8*12*Рычаги!$B$24 -> 0 | F34: =F6*F8*12*Рычаги!$B$24 -> 0 | G34: =G6*G8*12*Рычаги!$B$24 -> 0 | H34: =H6*H8*12*Рычаги!$B$24 -> 30000 | I34: =I6*I8*12*Рычаги!$B$24 -> 34999.98 | J34: =J6*J8*12*Рычаги!$B$24 -> 48000.024 | ... AL34: =AL6*AL8*12*Рычаги!$B$24 -> 378000
A35: Привлечение клиентов | B35: $/мес | C35: =C6*Рычаги!$B$25+C19*Рычаги!$B$26+C12*Рычаги!$B$27 -> 0 | D35: =D6*Рычаги!$B$25+D19*Рычаги!$B$26+D12*Рычаги!$B$27 -> 0 | E35: =E6*Рычаги!$B$25+E19*Рычаги!$B$26+E12*Рычаги!$B$27 -> 600 | F35: =F6*Рычаги!$B$25+F19*Рычаги!$B$26+F12*Рычаги!$B$27 -> 11200 | G35: =G6*Рычаги!$B$25+G19*Рычаги!$B$26+G12*Рычаги!$B$27 -> 16500 | H35: =H6*Рычаги!$B$25+H19*Рычаги!$B$26+H12*Рычаги!$B$27 -> 26800 | I35: =I6*Рычаги!$B$25+I19*Рычаги!$B$26+I12*Рычаги!$B$27 -> 27700 | J35: =J6*Рычаги!$B$25+J19*Рычаги!$B$26+J12*Рычаги!$B$27 -> 33300 | ... AL35: =AL6*Рычаги!$B$25+AL19*Рычаги!$B$26+AL12*Рычаги!$B$27 -> 438500
A36: Контент, платформа, юрлица | B36: $/мес | C36: =Рычаги!$B$29+Рычаги!$B$30+Рычаги!$B$31 -> 260000 | D36: =Рычаги!$B$29+Рычаги!$B$30+Рычаги!$B$31 -> 260000 | E36: =Рычаги!$B$29+Рычаги!$B$30+Рычаги!$B$31 -> 260000 | F36: =Рычаги!$B$29+Рычаги!$B$30+Рычаги!$B$31 -> 260000 | G36: =Рычаги!$B$29+Рычаги!$B$30+Рычаги!$B$31 -> 260000 | H36: =Рычаги!$B$29+Рычаги!$B$30+Рычаги!$B$31 -> 260000 | I36: =Рычаги!$B$29+Рычаги!$B$30+Рычаги!$B$31 -> 260000 | J36: =Рычаги!$B$29+Рычаги!$B$30+Рычаги!$B$31 -> 260000 | ... AL36: =Рычаги!$B$29+Рычаги!$B$30+Рычаги!$B$31 -> 260000
A37: Офис, поездки, софт | B37: $/мес | C37: =C32*Рычаги!$B$32 -> 18750 | D37: =D32*Рычаги!$B$32 -> 37500 | E37: =E32*Рычаги!$B$32 -> 56250 | F37: =F32*Рычаги!$B$32 -> 71250 | G37: =G32*Рычаги!$B$32 -> 88125 | H37: =H32*Рычаги!$B$32 -> 103125 | I37: =I32*Рычаги!$B$32 -> 116250 | J37: =J32*Рычаги!$B$32 -> 127500 | ... AL37: =AL32*Рычаги!$B$32 -> 356250
A38: Операционные всего | B38: $/мес | C38: =SUM(C32:C37) -> 403750 | D38: =SUM(D32:D37) -> 697500 | E38: =SUM(E32:E37) -> 841850 | F38: =SUM(F32:F37) -> 937450 | G38: =SUM(G32:G37) -> 1087125 | H38: =SUM(H32:H37) -> 1227425 | I38: =SUM(I32:I37) -> 1318950 | J38: =SUM(J32:J37) -> 1408800 | ... AL38: =SUM(AL32:AL37) -> 3837750
A39: ПРИБЫЛЬ И ДЕНЬГИ
A40: Расходы всего | B40: $/мес | C40: =C28+C38 -> 403750 | D40: =D28+D38 -> 698700 | E40: =E28+E38 -> 864490 | F40: =F28+F38 -> 960642 | G40: =G28+G38 -> 1111109 | H40: =H28+H38 -> 1265077 | I40: =I28+I38 -> 1389568 | J40: =J28+J38 -> 1517460 | ... AL40: =AL28+AL38 -> 6858277.5
...

Sheet Годы
A1: Отчёт о прибылях по годам · базовый сценарий
A2: Суммы по листу «Модель». До налогов, без капитальных затрат.
A4: $ | B4: Год 1 | C4: Год 2 | D4: Год 3
A5: Труд | B5: =SUM(Модель!C10:N10) -> 1863833.4 | C5: =SUM(Модель!O10:Z10) -> 29327500 | D5: =SUM(Модель!AA10:AL10) -> 69585000
A6: Личность: подписка | B6: =SUM(Модель!C15:N15) -> 204060 | C6: =SUM(Модель!O15:Z15) -> 7393760 | D6: =SUM(Модель!AA15:AL15) -> 17649280
A7: Личность: бренды | B7: =SUM(Модель!C17:N17) -> 1250000 | C7: =SUM(Модель!O17:Z17) -> 4300000 | D7: =SUM(Модель!AA17:AL17) -> 4800000
A8: Капитал | B8: =SUM(Модель!C22:N22) -> 527040 | C8: =SUM(Модель!O22:Z22) -> 7386720 | D8: =SUM(Модель!AA22:AL22) -> 18120000
A9: Выручка | B9: =SUM(Модель!C24:N24) -> 3844933.4 | C9: =SUM(Модель!O24:Z24) -> 48407980 | D9: =SUM(Модель!AA24:AL24) -> 110154280
A10: Себестоимость | B10: =SUM(Модель!C28:N28) -> 1189221 | C10: =SUM(Модель!O28:Z28) -> 13474698 | D10: =SUM(Модель!AA28:AL28) -> 29925820
A11: Валовая прибыль | B11: =SUM(Модель!C29:N29) -> 2655712.4 | C11: =SUM(Модель!O29:Z29) -> 34933282 | D11: =SUM(Модель!AA29:AL29) -> 80228460
A12: ФОТ | B12: =SUM(Модель!C32:N32) -> 8375000 | C12: =SUM(Модель!O32:Z32) -> 20100000 | D12: =SUM(Модель!AA32:AL32) -> 26475000
A13: Найм | B13: =SUM(Модель!C33:N33) -> 1275000 | C13: =SUM(Модель!O33:Z33) -> 975000 | D13: =SUM(Модель!AA33:AL33) -> 450000
A14: Комиссии продажам | B14: =SUM(Модель!C34:N34) -> 531000.01 | C14: =SUM(Модель!O34:Z34) -> 3921000 | D14: =SUM(Модель!AA34:AL34) -> 4536000
A15: Привлечение клиентов | B15: =SUM(Модель!C35:N35) -> 547850 | C15: =SUM(Модель!O35:Z35) -> 4370430 | D15: =SUM(Модель!AA35:AL35) -> 5262000
A16: Контент, платформа, юрлица | B16: =SUM(Модель!C36:N36) -> 3120000 | C16: =SUM(Модель!O36:Z36) -> 3120000 | D16: =SUM(Модель!AA36:AL36) -> 3120000
A17: Офис, поездки, софт | B17: =SUM(Модель!C37:N37) -> 1256250 | C17: =SUM(Модель!O37:Z37) -> 3015000 | D17: =SUM(Модель!AA37:AL37) -> 3971250
A18: Операционные всего | B18: =SUM(Модель!C38:N38) -> 15105100 | C18: =SUM(Модель!O38:Z38) -> 35501430 | D18: =SUM(Модель!AA38:AL38) -> 43814250
A19: EBITDA | B19: =SUM(Модель!C41:N41) -> -12449388 | C19: =SUM(Модель!O41:Z41) -> -568147.94 | D19: =SUM(Модель!AA41:AL41) -> 36414210
A20: Касса на конец года | B20: =Модель!N42 -> 37550612 | C20: =Модель!Z42 -> 36982464 | D20: =Модель!AL42 -> 73396674
A21: Валовая маржа | B21: =IF(B9=0,0,B11/B9) -> 0.69070439 | C21: =IF(C9=0,0,C11/C9) -> 0.72164304 | D21: =IF(D9=0,0,D11/D9) -> 0.72832812
A22: Маржа EBITDA | B22: =IF(B9=0,0,B19/B9) -> -3.2378682 | C22: =IF(C9=0,0,C19/C9) -> -0.011736659 | D22: =IF(D9=0,0,D19/D9) -> 0.33057463

Sheet Оценка
A1: Оценка как промежуточный результат
A2: Оценка = ARR направлений × мультипликаторы с листа «Рычаги» + выручка брендов за 12 месяцев. Мультипликаторы — допущение, их назначит рынок.
A4: Месяц | B4: ARR группы | C4: Оценка | D4: Для $1 млрд нужно | E4: Оценка / $1 млрд
A5: 12 | B5: =Модель!N26 -> 10224000 | C5: =Модель!N45 -> 96915000 | D5: =IF(B5=0,0,1000000000/B5) -> 97.809077 | E5: =C5/1000000000 -> 0.096915
A6: 18 | B6: =Модель!T26 -> 42344280 | C6: =Модель!T45 -> 387570120 | D6: =IF(B6=0,0,1000000000/B6) -> 23.615941 | E6: =C6/1000000000 -> 0.38757012
A7: 24 | B7: =Модель!Z26 -> 75127920 | C7: =Модель!Z45 -> 676609680 | D7: =IF(B7=0,0,1000000000/B7) -> 13.310631 | E7: =C7/1000000000 -> 0.67660968
A8: 30 | B8: =Модель!AF26 -> 103649400 | C8: =Модель!AF45 -> 937821600 | D8: =IF(B8=0,0,1000000000/B8) -> 9.6479092 | E8: =C8/1000000000 -> 0.9378216
A9: 36 | B9: =Модель!AL26 -> 129010920 | C9: =Модель!AL45 -> 1176427680 | D9: =IF(B9=0,0,1000000000/B9) -> 7.7512818 | E9: =C9/1000000000 -> 1.1764277

Sheet Проверки
A1: Итоги и сверка со стратегией
A2: Итоги считаются по листу «Модель». Сверка — с target-state-18m.md и декой v10 на 18-й месяц.
A4: Показатель | B4: В стратегии | C4: В модели | D4: Сходится
A5: ИТОГИ
A6: Выход в устойчивый плюс, месяц | C6: =IFERROR(MATCH(1,Модель!C43:AL43,0),"нет за 36 мес.") -> 19
A7: Дно кассы, $ | C7: =MIN(Модель!C42:AL42) -> 32584842
A8: Месяц дна кассы | C8: =MATCH(MIN(Модель!C42:AL42),Модель!C42:AL42,0) -> 18
A9: Касса к 36-му месяцу, $ | C9: =Модель!AL42 -> 73396674
A10: Оценка к 36-му месяцу, $ | C10: =Модель!AL45 -> 1176427680
A12: СВЕРКА НА 18-Й МЕСЯЦ
A13: ARR группы | B13: 42000000 | C13: =Модель!T26 -> 42344280 | D13: =IF(ABS(C13-B13)<=1500000,"да","НЕТ") -> да
A14: Выручка 18-го месяца | B14: 3600000 | C14: =Модель!T24 -> 3928690 | D14: =IF(ABS(C14-B14)<=400000,"да","НЕТ") -> да
A15: Расход 18-го месяца | B15: 4000000 | C15: =Модель!T40 -> 4225147.5 | D15: =IF(ABS(C15-B15)<=400000,"да","НЕТ") -> да
A16: Деньги на счету | B16: 21000000 | C16: =Модель!T42 -> 32584842 | D16: =IF(ABS(C16-B16)<=2000000,"да","НЕТ") -> НЕТ
A17: Труд: компаний | B17: 157 | C17: =Модель!T7 -> 159 | D17: =IF(ABS(C17-B17)<=5,"да","НЕТ") -> да
A18: Капитал: компаний | B18: 256 | C18: =Модель!T20 -> 292 | D18: =IF(ABS(C18-B18)<=10,"да","НЕТ") -> НЕТ
A19: Личность: подписчиков | B19: 63500 | C19: =Модель!T14 -> 55969 | D19: =IF(ABS(C19-B19)<=2000,"да","НЕТ") -> НЕТ
A20: Штат | B20: 135 | C20: =Модель!T31 -> 135 | D20: =IF(ABS(C20-B20)<=5,"да","НЕТ") -> да
A21: Расходы этапа 1, мес. 1–3 | B21: 3710000 | C21: =SUM(Модель!C40:E40) -> 1966940 | D21: =IF(ABS(C21-B21)<=556500,"да","НЕТ") -> НЕТ
A22: Расходы этапа 2, мес. 4–6 | B22: 5700000 | C22: =SUM(Модель!F40:H40) -> 3336828 | D22: =IF(ABS(C22-B22)<=855000,"да","НЕТ") -> НЕТ
A23: Расходы этапа 3, мес. 7–12 | B23: 14200000 | C23: =SUM(Модель!I40:N40) -> 10990553 | D23: =IF(ABS(C23-B23)<=2130000,"да","НЕТ") -> НЕТ
A24: Расходы этапа 4, мес. 13–18 | B24: 18400000 | C24: =SUM(Модель!O40:T40) -> 20043921 | D24: =IF(ABS(C24-B24)<=2760000,"да","НЕТ") -> да
A26: Допуск — в формуле колонки «Сходится», под порядок величины. Расходы этапов сверяются с допуском 15%.
